Workbook

Sheet EMP_MASTER
A1: Emp_ID | B1: Full_Name | C1: Department | D1: Designation | E1: Date_of_Joining | F1: Employment_Type | G1: Basic_Salary | H1: HRA_% | I1: DA_% | J1: Bank_Account | K1: PAN | L1: Status
A2: EMP001 | B2: Aarav | C2: Operations | D2: Associate / Operator | E2: 45146 | F2: Full-Time | G2: 12000 | H2: 0.2 | I2: 0.08 | J2: HDFC0001234 | K2: ABCPD1234A | L2: Active
A3: EMP002 | B3: Vivaan | C3: Operations | D3: Associate / Operator | E3: 43957 | F3: Full-Time | G3: 13000 | H3: 0.2 | I3: 0.08 | J3: HDFC0002345 | K3: QWERT5678Z | L3: Active
A4: EMP003 | B4: Aditya | C4: Operations | D4: Associate / Operator | E4: 45670 | F4: Full-Time | G4: 13500 | H4: 0.2 | I4: 0.08 | J4: HDFC0003456 | K4: ZXCVB2345K | L4: Active
A5: EMP004 | B5: Arjun | C5: Operations | D5: Associate / Operator | E5: 44816 | F5: Contract | G5: 15000 | H5: 0.2 | I5: 0.08 | J5: HDFC0004567 | K5: LMNOP6789Q | L5: Active
A6: EMP005 | B6: Reyansh | C6: Operations | D6: Executive | E6: 43432 | F6: Full-Time | G6: 27000 | H6: 0.3 | I6: 0.1 | J6: HDFC0005678 | K6: ASDFG3456H | L6: Resigned
A7: EMP006 | B7: Muhammad | C7: Operations | D7: Associate / Operator | E7: 43400 | F7: Full-Time | G7: 17000 | H7: 0.2 | I7: 0.08 | J7: HDFC0006789 | K7: GHJKL7890P | L7: Active
A8: EMP007 | B8: Krishna | C8: Operations | D8: Associate / Operator | E8: 45600 | F8: Full-Time | G8: 15000 | H8: 0.2 | I8: 0.08 | J8: HDFC0007890 | K8: POIUY4567M | L8: Active
A9: EMP008 | B9: Ishaan | C9: Operations | D9: Associate / Operator | E9: 45736 | F9: Full-Time | G9: 14000 | H9: 0.2 | I9: 0.08 | J9: HDFC0008901 | K9: TREWA8901X | L9: Active
A10: EMP009 | B10: Shaurya | C10: Operations | D10: Executive | E10: 44099 | F10: Contract | G10: 23000 | H10: 0.3 | I10: 0.1 | J10: HDFC0009012 | K10: LKJHG5678R | L10: Active
A11: EMP010 | B11: Atharv | C11: Operations | D11: Associate / Operator | E11: 44587 | F11: Full-Time | G11: 14000 | H11: 0.2 | I11: 0.08 | J11: HDFC0001122 | K11: MNBVC9012S | L11: Active
A12: EMP011 | B12: Kabir | C12: Operations | D12: Manager | E12: 43174 | F12: Full-Time | G12: 55000 | H12: 0.4 | I12: 0.15 | J12: HDFC0002233 | K12: YUIOP6789D | L12: Active
A13: EMP012 | B13: Rohan | C13: Operations | D13: Associate / Operator | E13: 43682 | F13: Full-Time | G13: 18000 | H13: 0.2 | I13: 0.08 | J13: HDFC0003344 | K13: HGFDS1234L | L13: On Leave
... A39: EMP038 | B39: Vijay | C39: Warehouse | D39: Associate / Operator | E39: 45627 | F39: Contract | G39: 13000 | H39: 0.2 | I39: 0.08 | J39: SBIN0003344 | K39: WERTY9898T | L39: Active
A40: EMP039 | B40: Sunil | C40: Warehouse | D40: Associate / Operator | E40: 44539 | F40: Full-Time | G40: 16000 | I40: 0.08 | J40: SBIN0004455 | K40: ERTYU0909U | L40: Active
A41: EMP040 | B41: Anil | C41: Warehouse | D41: Senior Executive | E41: 45367 | F41: Full-Time | G41: 36000 | H41: 0.3 | I41: 0.12 | J41: SBIN0005566 | K41: RTYUI1111V | L41: Active
A42: EMP041 | B42: Mukesh | C42: Warehouse | D42: Executive | E42: 45997 | F42: Full-Time | G42: 22000 | H42: 0.3 | I42: 0.1 | J42: SBIN0006677 | K42: TYUIO2222W | L42: Active
A43: EMP042 | B43: Rajesh | C43: Warehouse | D43: Executive | E43: 45331 | F43: Full-Time | G43: 24000 | H43: 0.3 | I43: 0.1 | J43: SBIN0007788 | K43: YUIOP3333X | L43: Active
A44: EMP043 | B44: Mahesh | C44: Warehouse | D44: Executive | E44: 43486 | F44: Contract | G44: 21000 | H44: 0.3 | I44: 0.1 | J44: SBIN0008899 | K44: UIOPL4444Y | L44: Active
A45: EMP044 | B45: Prakash | C45: Warehouse | D45: Executive | E45: 43479 | F45: Full-Time | G45: 28000 | H45: 0.3 | I45: 0.1 | J45: SBIN0009900 | K45: IOPLK5555Z | L45: Active
A46: EMP045 | B46: Shivam | C46: Warehouse | D46: Executive | E46: 45627 | F46: Full-Time | G46: 23000 | H46: 0.3 | I46: 0.1 | J46: SBIN0001010 | K46: OPLKM6666A | L46: Active
A47: EMP046 | B47: Om | C47: Warehouse | D47: Senior Executive | E47: 43181 | F47: Full-Time | G47: 33000 | H47: 0.35 | I47: 0.12 | J47: SBIN0002020 | K47: PLKJH7777B | L47: Active
A48: EMP047 | B48: Akash | C48: Warehouse | D48: Associate / Operator | E48: 44223 | F48: Contract | G48: 13000 | H48: 0.2 | I48: 0.08 | J48: SBIN0003030 | K48: LKJHG8888C | L48: Active
A49: EMP048 | B49: Kartik | C49: Warehouse | D49: Associate / Operator | E49: 43195 | F49: Full-Time | G49: 14000 | H49: 0.2 | I49: 0.08 | J49: SBIN0004040 | K49: KJHGF9999D | L49: Active
A50: EMP049 | B50: Aryan | C50: Warehouse | D50: Associate / Operator | E50: 43904 | F50: Full-Time | G50: 16000 | H50: 0.2 | I50: 0.08 | J50: SBIN0005050 | K50: JHGFD0000E | L50: Active
A51: EMP050 | B51: Sagar | C51: Warehouse | D51: Associate / Operator | E51: 44724 | F51: Contract | G51: 15000 | H51: 0.2 | I51: 0.08 | J51: SBIN0006060 | K51: HGFDS1212F | L51: Active
A52: EMP051 | B52: Naveen | C52: Warehouse | D52: Manager | E52: 43691 | F52: Full-Time | G52: 48000 | H52: 0.4 | I52: 0.15 | J52: SBIN0007070 | K52: GFDSA2323G | L52: Active
... A105: EMP104 | B105: Prem | C105: IT | D105: Manager | E105: 43269 | F105: Full-Time | G105: 56000 | H105: 0.4 | I105: 0.15 | J105: HDFC0003582 | K105: LKJHG7779M | L105: Active
A106: EMP105 | B106: Kamal | C106: IT | D106: Senior Executive | E106: 44686 | F106: Full-Time | G106: 42000 | H106: 0.35 | I106: 0.12 | J106: HDFC0004693 | L106: Active
A107: EMP106 | B107: Jagdish | C107: IT | D107: Executive | E107: 45253 | F107: Full-Time | G107: 26000 | H107: 0.3 | I107: 0.1 | J107: HDFC0005704 | L107: Active

Sheet Attendance
A1: Emp_ID | B1: Emp_Name | C1: Department | D1: 01-Jan-25 | E1: 02-Jan-25 | F1: 03-Jan-25 | G1: 04-Jan-25 | H1: 05-Jan-25 | I1: 06-Jan-25 | J1: 07-Jan-25 | K1: 08-Jan-25 | L1: 09-Jan-25 | M1: 10-Jan-25 | N1: 11-Jan-25 | O1: 12-Jan-25 | P1: 13-Jan-25 | Q1: 14-Jan-25 | R1: 15-01-2025 | S1: 16-Jan-25 | T1: 17-Jan-25 | U1: 18-Jan-25 | V1: 19-Jan-25 | W1: 20-Jan-25 | X1: 21-Jan-25 | Y1: 22-Jan-25 | Z1: 23-Jan-25 | AA1: 24-Jan-25 | AB1: 25-Jan-25 | AC1: 26-Jan-25 | AD1: 27-Jan-25 | AE1: 28-Jan-25 | AF1: 29-01-2025 | AG1: 30-Jan-25 | AH1: 31-Jan-25 | AI1: Total Present | AJ1: Total Absent | AK1: Casual Leave (CL) | AL1: Sick Leave (SL) | AM1: Earned Leave (EL) | AN1: Late Marks | AO1: Working Days | AP1: Attendance %
A2: EMP001 | B2: =_xlfn.XLOOKUP(A2,Table1[Emp_ID],Table1[Full_Name ]) -> Aarav | C2: =_xlfn.XLOOKUP(A2,Table1[Emp_ID],Table1[Department]) -> Operations | D2: P | E2: P | F2: P | G2: P | H2: H | I2: P | J2: P | K2: P | L2: P | M2: A | N2: P | O2: H | P2: H | Q2: P | R2: P | S2: P | T2: P | U2: P | V2: H | W2: P | X2: P | Y2: P | Z2: P | AA2: P | AB2: P | AC2: H | AD2: P | AE2: P | AF2: P | AG2: SL | AH2: SL | AI2: =COUNTIF(D2:AH2,"P") -> 23 | AJ2: =COUNTIF(D2:AH2,"A") -> 1 | AK2: =COUNTIF(D2:AH2,"CL") -> 0 | AL2: =COUNTIF(D2:AH2,"SL") -> 2 | AM2: =COUNTIF(D2:AH2,"EL") -> 0 | AN2: =COUNTIF(D2:AH2,"L") -> 0 | AO2: =COUNTIF(D2:AH2,"P")+COUNTIF(D2:AH2,"CL")+COUNTIF(D2:AH2,"SL")+COUNTIF(D2:AH2,"EL") -> 25 | AP2: =AO2/26*100 -> 96.153846
A3: EMp002 | B3: =_xlfn.XLOOKUP(A3,Table1[Emp_ID],Table1[Full_Name ]) -> Vivaan | C3: =_xlfn.XLOOKUP(A3,Table1[Emp_ID],Table1[Department]) -> Operations | D3: P | E3: A | F3: P | G3: P | H3: H | I3: P | J3: P | K3: P | L3: P | M3: P | N3: P | O3: H | P3: H | Q3: P | R3: P | S3: P | T3: P | U3: P | V3: H | W3: P | X3: P | Y3: P | Z3: P | AA3: P | AB3: P | AC3: H | AD3: P | AE3: P | AF3: P | AG3: P | AH3: P | AI3: =COUNTIF(D3:AH3,"P") -> 25 | AJ3: =COUNTIF(D3:AH3,"A") -> 1 | AK3: =COUNTIF(D3:AH3,"CL") -> 0 | AL3: =COUNTIF(D3:AH3,"SL") -> 0 | AM3: =COUNTIF(D3:AH3,"EL") -> 0 | AN3: =COUNTIF(D3:AH3,"L") -> 0 | AO3: =COUNTIF(D3:AH3,"P")+COUNTIF(D3:AH3,"CL")+COUNTIF(D3:AH3,"SL")+COUNTIF(D3:AH3,"EL") -> 25 | AP3: =AO3/26*100 -> 96.153846
A4: EMP003 | B4: =_xlfn.XLOOKUP(A4,Table1[Emp_ID],Table1[Full_Name ]) -> Aditya | C4: =_xlfn.XLOOKUP(A4,Table1[Emp_ID],Table1[Department]) -> Operations | D4: P | E4: P | F4: P | G4: P | H4: H | I4: P | J4: P | K4: L | L4: P | M4: P | N4: P | O4: H | P4: H | Q4: P | R4: P | S4: P | T4: P | U4: P | V4: H | W4: P | X4: P | Y4: P | Z4: P | AA4: P | AB4: P | AC4: H | AD4: P | AE4: P | AF4: P | AG4: P | AH4: P | AI4: =COUNTIF(D4:AH4,"P") -> 25 | AJ4: =COUNTIF(D4:AH4,"A") -> 0 | AK4: =COUNTIF(D4:AH4,"CL") -> 0 | AL4: =COUNTIF(D4:AH4,"SL") -> 0 | AM4: =COUNTIF(D4:AH4,"EL") -> 0 | AN4: =COUNTIF(D4:AH4,"L") -> 1 | AO4: =COUNTIF(D4:AH4,"P")+COUNTIF(D4:AH4,"CL")+COUNTIF(D4:AH4,"SL")+COUNTIF(D4:AH4,"EL") -> 25 | AP4: =AO4/26*100 -> 96.153846
A5: EMP004 | B5: =_xlfn.XLOOKUP(A5,Table1[Emp_ID],Table1[Full_Name ]) -> Arjun | C5: =_xlfn.XLOOKUP(A5,Table1[Emp_ID],Table1[Department]) -> Operations | D5: P | E5: P | F5: P | G5: A | H5: H | I5: P | J5: P | K5: P | L5: P | M5: P | N5: P | O5: H | P5: H | Q5: P | R5: P | S5: P | T5: P | U5: P | V5: H | W5: P | X5: P | Y5: P | Z5: P | AA5: P | AB5: P | AC5: H | AD5: P | AE5: P | AF5: P | AG5: P | AH5: P | AI5: =COUNTIF(D5:AH5,"P") -> 25 | AJ5: =COUNTIF(D5:AH5,"A") -> 1 | AK5: =COUNTIF(D5:AH5,"CL") -> 0 | AL5: =COUNTIF(D5:AH5,"SL") -> 0 | AM5: =COUNTIF(D5:AH5,"EL") -> 0 | AN5: =COUNTIF(D5:AH5,"L") -> 0 | AO5: =COUNTIF(D5:AH5,"P")+COUNTIF(D5:AH5,"CL")+COUNTIF(D5:AH5,"SL")+COUNTIF(D5:AH5,"EL") -> 25 | AP5: =AO5/26*100 -> 96.153846
A6: EMP005 | B6: =_xlfn.XLOOKUP(A6,Table1[Emp_ID],Table1[Full_Name ]) -> Reyansh | C6: =_xlfn.XLOOKUP(A6,Table1[Emp_ID],Table1[Department]) -> Operations | D6: P | E6: P | F6: P | G6: P | H6: H | I6: P | J6: P | K6: P | L6: A | M6: P | N6: P | O6: H | P6: H | Q6: P | R6: P | S6: P | T6: P | U6: P | V6: H | W6: P | X6: EL | Y6: EL | Z6: EL | AA6: EL | AB6: P | AC6: H | AD6: P | AE6: P | AF6: P | AG6: P | AH6: P | AI6: =COUNTIF(D6:AH6,"P") -> 21 | AJ6: =COUNTIF(D6:AH6,"A") -> 1 | AK6: =COUNTIF(D6:AH6,"CL") -> 0 | AL6: =COUNTIF(D6:AH6,"SL") -> 0 | AM6: =COUNTIF(D6:AH6,"EL") -> 4 | AN6: =COUNTIF(D6:AH6,"L") -> 0 | AO6: =COUNTIF(D6:AH6,"P")+COUNTIF(D6:AH6,"CL")+COUNTIF(D6:AH6,"SL")+COUNTIF(D6:AH6,"EL") -> 25 | AP6: =AO6/26*100 -> 96.153846
A7: EMP006 | B7: =_xlfn.XLOOKUP(A7,Table1[Emp_ID],Table1[Full_Name ]) -> Muhammad | C7: =_xlfn.XLOOKUP(A7,Table1[Emp_ID],Table1[Department]) -> Operations | D7: P | E7: P | F7: P | G7: P | H7: H | I7: P | J7: P | K7: P | L7: P | M7: P | N7: P | O7: H | P7: H | Q7: P | R7: P | S7: P | T7: P | U7: P | V7: H | W7: P | X7: P | Y7: P | Z7: P | AA7: P | AB7: P | AC7: H | AD7: P | AE7: P | AF7: P | AG7: P | AH7: P | AI7: =COUNTIF(D7:AH7,"P") -> 26 | AJ7: =COUNTIF(D7:AH7,"A") -> 0 | AK7: =COUNTIF(D7:AH7,"CL") -> 0 | AL7: =COUNTIF(D7:AH7,"SL") -> 0 | AM7: =COUNTIF(D7:AH7,"EL") -> 0 | AN7: =COUNTIF(D7:AH7,"L") -> 0 | AO7: =COUNTIF(D7:AH7,"P")+COUNTIF(D7:AH7,"CL")+COUNTIF(D7:AH7,"SL")+COUNTIF(D7:AH7,"EL") -> 26 | AP7: =AO7/26*100 -> 100
A8: EMP007 | B8: =_xlfn.XLOOKUP(A8,Table1[Emp_ID],Table1[Full_Name ]) -> Krishna | C8: =_xlfn.XLOOKUP(A8,Table1[Emp_ID],Table1[Department]) -> Operations | D8: A | E8: P | F8: P | G8: P | H8: H | I8: P | J8: P | K8: P | L8: P | M8: P | N8: P | O8: H | P8: H | Q8: P | R8: P | S8: P | T8: P | U8: P | V8: H | W8: P | X8: P | Y8: P | Z8: P | AA8: P | AB8: P | AC8: H | AD8: P | AE8: P | AF8: P | AG8: P | AH8: P | AI8: =COUNTIF(D8:AH8,"P") -> 25 | AJ8: =COUNTIF(D8:AH8,"A") -> 1 | AK8: =COUNTIF(D8:AH8,"CL") -> 0 | AL8: =COUNTIF(D8:AH8,"SL") -> 0 | AM8: =COUNTIF(D8:AH8,"EL") -> 0 | AN8: =COUNTIF(D8:AH8,"L") -> 0 | AO8: =COUNTIF(D8:AH8,"P")+COUNTIF(D8:AH8,"CL")+COUNTIF(D8:AH8,"SL")+COUNTIF(D8:AH8,"EL") -> 25 | AP8: =AO8/26*100 -> 96.153846
A9: EMP008 | B9: =_xlfn.XLOOKUP(A9,Table1[Emp_ID],Table1[Full_Name ]) -> Ishaan | C9: =_xlfn.XLOOKUP(A9,Table1[Emp_ID],Table1[Department]) -> Operations | D9: P | E9: P | F9: P | G9: P | H9: H | I9: P | J9: A | K9: P | L9: P | M9: P | N9: P | O9: H | P9: H | Q9: P | R9: CL | S9: CL | T9: P | U9: P | V9: H | W9: P | X9: P | Y9: P | Z9: P | AA9: P | AB9: P | AC9: H | AD9: P | AE9: P | AF9: P | AG9: P | AH9: P | AI9: =COUNTIF(D9:AH9,"P") -> 23 | AJ9: =COUNTIF(D9:AH9,"A") -> 1 | AK9: =COUNTIF(D9:AH9,"CL") -> 2 | AL9: =COUNTIF(D9:AH9,"SL") -> 0 | AM9: =COUNTIF(D9:AH9,"EL") -> 0 | AN9: =COUNTIF(D9:AH9,"L") -> 0 | AO9: =COUNTIF(D9:AH9,"P")+COUNTIF(D9:AH9,"CL")+COUNTIF(D9:AH9,"SL")+COUNTIF(D9:AH9,"EL") -> 25 | AP9: =AO9/26*100 -> 96.153846
A10: EMP009 | B10: =_xlfn.XLOOKUP(A10,Table1[Emp_ID],Table1[Full_Name ]) -> Shaurya | C10: =_xlfn.XLOOKUP(A10,Table1[Emp_ID],Table1[Department]) -> Operations | D10: P | E10: P | F10: P | G10: P | H10: H | I10: P | J10: P | K10: P | L10: P | M10: P | N10: P | O10: H | P10: H | Q10: P | R10: P | S10: P | T10: P | U10: P | V10: H | W10: P | X10: P | Y10: P | Z10: SL | AA10: SL | AB10: P | AC10: H | AD10: P | AE10: P | AF10: P | AG10: P | AH10: P | AI10: =COUNTIF(D10:AH10,"P") -> 24 | AJ10: =COUNTIF(D10:AH10,"A") -> 0 | AK10: =COUNTIF(D10:AH10,"CL") -> 0 | AL10: =COUNTIF(D10:AH10,"SL") -> 2 | AM10: =COUNTIF(D10:AH10,"EL") -> 0 | AN10: =COUNTIF(D10:AH10,"L") -> 0 | AO10: =COUNTIF(D10:AH10,"P")+COUNTIF(D10:AH10,"CL")+COUNTIF(D10:AH10,"SL")+COUNTIF(D10:AH10,"EL") -> 26 | AP10: =AO10/26*100 -> 100
A11: EMP010 | B11: =_xlfn.XLOOKUP(A11,Table1[Emp_ID],Table1[Full_Name ]) -> Atharv | C11: =_xlfn.XLOOKUP(A11,Table1[Emp_ID],Table1[Department]) -> Operations | D11: P | E11: P | F11: P | G11: P | H11: H | I11: P | J11: P | K11: P | L11: P | M11: P | N11: P | O11: H | P11: H | Q11: A | R11: P | S11: P | T11: P | U11: P | V11: H | W11: P | X11: P | Y11: P | Z11: P | AA11: P | AB11: P | AC11: H | AD11: P | AE11: P | AF11: P | AG11: P | AH11: P | AI11: =COUNTIF(D11:AH11,"P") -> 25 | AJ11: =COUNTIF(D11:AH11,"A") -> 1 | AK11: =COUNTIF(D11:AH11,"CL") -> 0 | AL11: =COUNTIF(D11:AH11,"SL") -> 0 | AM11: =COUNTIF(D11:AH11,"EL") -> 0 | AN11: =COUNTIF(D11:AH11,"L") -> 0 | AO11: =COUNTIF(D11:AH11,"P")+COUNTIF(D11:AH11,"CL")+COUNTIF(D11:AH11,"SL")+COUNTIF(D11:AH11,"EL") -> 25 | AP11: =AO11/26*100 -> 96.153846
A12: EMP011 | B12: =_xlfn.XLOOKUP(A12,Table1[Emp_ID],Table1[Full_Name ]) -> Kabir | C12: =_xlfn.XLOOKUP(A12,Table1[Emp_ID],Table1[Department]) -> Operations | D12: P | E12: P | F12: P | G12: P | H12: H | I12: P | J12: P | K12: P | L12: P | M12: P | N12: P | O12: H | P12: H | Q12: P | R12: P | S12: P | T12: P | U12: P | V12: H | W12: P | X12: P | Y12: P | Z12: P | AA12: P | AB12: P | AC12: H | AD12: P | AE12: P | AF12: P | AG12: A | AH12: P | AI12: =COUNTIF(D12:AH12,"P") -> 25 | AJ12: =COUNTIF(D12:AH12,"A") -> 1 | AK12: =COUNTIF(D12:AH12,"CL") -> 0 | AL12: =COUNTIF(D12:AH12,"SL") -> 0 | AM12: =COUNTIF(D12:AH12,"EL") -> 0 | AN12: =COUNTIF(D12:AH12,"L") -> 0 | AO12: =COUNTIF(D12:AH12,"P")+COUNTIF(D12:AH12,"CL")+COUNTIF(D12:AH12,"SL")+COUNTIF(D12:AH12,"EL") -> 25 | AP12: =AO12/26*100 -> 96.153846
A13: EMP012 | B13: =_xlfn.XLOOKUP(A13,Table1[Emp_ID],Table1[Full_Name ]) -> Rohan | C13: =_xlfn.XLOOKUP(A13,Table1[Emp_ID],Table1[Department]) -> Operations | D13: P | E13: P | F13: P | G13: P | H13: H | I13: P | J13: P | K13: P | L13: P | M13: P | N13: P | O13: H | P13: H | Q13: P | R13: P | S13: P | T13: P | U13: P | V13: H | W13: P | X13: P | Y13: P | Z13: P | AA13: P | AB13: P | AC13: H | AD13: P | AE13: P | AF13: P | AG13: P | AH13: P | AI13: =COUNTIF(D13:AH13,"P") -> 26 | AJ13: =COUNTIF(D13:AH13,"A") -> 0 | AK13: =COUNTIF(D13:AH13,"CL") -> 0 | AL13: =COUNTIF(D13:AH13,"SL") -> 0 | AM13: =COUNTIF(D13:AH13,"EL") -> 0 | AN13: =COUNTIF(D13:AH13,"L") -> 0 | AO13: =COUNTIF(D13:AH13,"P")+COUNTIF(D13:AH13,"CL")+COUNTIF(D13:AH13,"SL")+COUNTIF(D13:AH13,"EL") -> 26 | AP13: =AO13/26*100 -> 100
... A66: EMP065 | B66: =_xlfn.XLOOKUP(A66,Table1[Emp_ID],Table1[Full_Name ]) -> Wasim | C66: =_xlfn.XLOOKUP(A66,Table1[Emp_ID],Table1[Department]) -> Marketing | D66: P | E66: P | F66: P | G66: P | H66: H | I66: P | J66: P | K66: P | L66: P | M66: P | N66: P | O66: H | P66: H | Q66: A | R66: P | S66: P | T66: P | U66: P | V66: H | W66: P | X66: P | Y66: P | Z66: P | AA66: P | AB66: P | AC66: H | AD66: P | AE66: P | AF66: P | AG66: P | AH66: P | AI66: =COUNTIF(D66:AH66,"P") -> 25 | AJ66: =COUNTIF(D66:AH66,"A") -> 1 | AK66: =COUNTIF(D66:AH66,"CL") -> 0 | AL66: =COUNTIF(D66:AH66,"SL") -> 0 | AM66: =COUNTIF(D66:AH66,"EL") -> 0 | AN66: =COUNTIF(D66:AH66,"L") -> 0 | AO66: =COUNTIF(D66:AH66,"P")+COUNTIF(D66:AH66,"CL")+COUNTIF(D66:AH66,"SL")+COUNTIF(D66:AH66,"EL") -> 25 | AP66: =AO66/26*100 -> 96.153846
A67: EMP066 | B67: =_xlfn.XLOOKUP(A67,Table1[Emp_ID],Table1[Full_Name ]) -> Farhan | C67: =_xlfn.XLOOKUP(A67,Table1[Emp_ID],Table1[Department]) -> Marketing | D67: P | E67: P | F67: P | G67: P | H67: H | I67: P | J67: P | K67: A | L67: P | M67: P | N67: P | O67: H | P67: H | Q67: P | R67: P | S67: P | T67: P | U67: P | V67: H | W67: P | X67: P | Y67: P | Z67: P | AA67: A | AB67: P | AC67: H | AD67: P | AE67: P | AF67: P | AG67: P | AI67: =COUNTIF(D67:AH67,"P") -> 23 | AJ67: =COUNTIF(D67:AH67,"A") -> 2 | AK67: =COUNTIF(D67:AH67,"CL") -> 0 | AL67: =COUNTIF(D67:AH67,"SL") -> 0 | AM67: =COUNTIF(D67:AH67,"EL") -> 0 | AN67: =COUNTIF(D67:AH67,"L") -> 0 | AO67: =COUNTIF(D67:AH67,"P")+COUNTIF(D67:AH67,"CL")+COUNTIF(D67:AH67,"SL")+COUNTIF(D67:AH67,"EL") -> 23 | AP67: =AO67/26*100 -> 88.461538
A68: EMP067 | B68: =_xlfn.XLOOKUP(A68,Table1[Emp_ID],Table1[Full_Name ]) -> Bilal | C68: =_xlfn.XLOOKUP(A68,Table1[Emp_ID],Table1[Department]) -> Marketing | D68: P | E68: P | F68: P | G68: P | H68: H | I68: P | J68: P | K68: P | L68: P | M68: P | N68: P | O68: H | P68: H | Q68: P | R68: P | S68: P | T68: P | U68: P | V68: H | W68: P | X68: P | Y68: P | Z68: P | AA68: P | AB68: P | AC68: H | AD68: P | AE68: P | AF68: P | AG68: P | AH68: P | AI68: =COUNTIF(D68:AH68,"P") -> 26 | AJ68: =COUNTIF(D68:AH68,"A") -> 0 | AK68: =COUNTIF(D68:AH68,"CL") -> 0 | AL68: =COUNTIF(D68:AH68,"SL") -> 0 | AM68: =COUNTIF(D68:AH68,"EL") -> 0 | AN68: =COUNTIF(D68:AH68,"L") -> 0 | AO68: =COUNTIF(D68:AH68,"P")+COUNTIF(D68:AH68,"CL")+COUNTIF(D68:AH68,"SL")+COUNTIF(D68:AH68,"EL") -> 26 | AP68: =AO68/26*100 -> 100
A69: EMP068 | B69: =_xlfn.XLOOKUP(A69,Table1[Emp_ID],Table1[Full_Name ]) -> Aamir | C69: =_xlfn.XLOOKUP(A69,Table1[Emp_ID],Table1[Department]) -> Marketing | D69: P | E69: EL | F69: EL | G69: EL | H69: H | I69: P | J69: P | K69: P | L69: P | M69: P | N69: P | O69: H | P69: H | Q69: P | R69: P | S69: P | T69: P | U69: A | V69: H | W69: P | X69: P | Y69: L | Z69: P | AA69: P | AB69: P | AC69: H | AD69: P | AE69: P | AF69: P | AG69: P | AH69: P | AI69: =COUNTIF(D69:AH69,"P") -> 21 | AJ69: =COUNTIF(D69:AH69,"A") -> 1 | AK69: =COUNTIF(D69:AH69,"CL") -> 0 | AL69: =COUNTIF(D69:AH69,"SL") -> 0 | AM69: =COUNTIF(D69:AH69,"EL") -> 3 | AN69: =COUNTIF(D69:AH69,"L") -> 1 | AO69: =COUNTIF(D69:AH69,"P")+COUNTIF(D69:AH69,"CL")+COUNTIF(D69:AH69,"SL")+COUNTIF(D69:AH69,"EL") -> 24 | AP69: =AO69/26*100 -> 92.307692
A70: EMP069 | B70: =_xlfn.XLOOKUP(A70,Table1[Emp_ID],Table1[Full_Name ]) -> Shahid | C70: =_xlfn.XLOOKUP(A70,Table1[Emp_ID],Table1[Department]) -> Marketing | D70: P | E70: P | F70: P | G70: P | H70: H | I70: P | J70: A | K70: P | L70: P | M70: P | N70: P | O70: H | P70: H | Q70: SL | R70: P | S70: P | T70: P | U70: P | V70: H | W70: P | X70: P | Y70: P | Z70: P | AA70: P | AB70: P | AC70: H | AD70: P | AE70: P | AF70: P | AG70: P | AH70: P | AI70: =COUNTIF(D70:AH70,"P") -> 24 | AJ70: =COUNTIF(D70:AH70,"A") -> 1 | AK70: =COUNTIF(D70:AH70,"CL") -> 0 | AL70: =COUNTIF(D70:AH70,"SL") -> 1 | AM70: =COUNTIF(D70:AH70,"EL") -> 0 | AN70: =COUNTIF(D70:AH70,"L") -> 0 | AO70: =COUNTIF(D70:AH70,"P")+COUNTIF(D70:AH70,"CL")+COUNTIF(D70:AH70,"SL")+COUNTIF(D70:AH70,"EL") -> 25 | AP70: =AO70/26*100 -> 96.153846
A71: EMP070 | B71: =_xlfn.XLOOKUP(A71,Table1[Emp_ID],Table1[Full_Name ]) -> Nadeem | C71: =_xlfn.XLOOKUP(A71,Table1[Emp_ID],Table1[Department]) -> Marketing | D71: P | E71: P | F71: P | G71: P | H71: H | I71: P | J71: P | K71: P | L71: P | M71: P | N71: A | O71: H | P71: H | Q71: P | R71: P | S71: P | T71: P | U71: P | V71: H | W71: P | X71: P | Y71: P | Z71: A | AA71: P | AB71: P | AC71: H | AD71: P | AE71: P | AF71: P | AG71: P | AH71: P | AI71: =COUNTIF(D71:AH71,"P") -> 24 | AJ71: =COUNTIF(D71:AH71,"A") -> 2 | AK71: =COUNTIF(D71:AH71,"CL") -> 0 | AL71: =COUNTIF(D71:AH71,"SL") -> 0 | AM71: =COUNTIF(D71:AH71,"EL") -> 0 | AN71: =COUNTIF(D71:AH71,"L") -> 0 | AO71: =COUNTIF(D71:AH71,"P")+COUNTIF(D71:AH71,"CL")+COUNTIF(D71:AH71,"SL")+COUNTIF(D71:AH71,"EL") -> 24 | AP71: =AO71/26*100 -> 92.307692
A72: EMP071 | B72: =_xlfn.XLOOKUP(A72,Table1[Emp_ID],Table1[Full_Name ]) -> Parth | C72: =_xlfn.XLOOKUP(A72,Table1[Emp_ID],Table1[Department]) -> Support | D72: P | E72: P | F72: P | G72: P | H72: H | I72: P | J72: P | K72: P | L72: P | M72: P | N72: P | O72: H | P72: H | Q72: P | R72: P | S72: P | T72: P | U72: P | V72: H | W72: P | X72: P | Y72: P | Z72: P | AA72: P | AB72: P | AC72: H | AD72: P | AE72: P | AF72: P | AG72: P | AH72: P | AI72: =COUNTIF(D72:AH72,"P") -> 26 | AJ72: =COUNTIF(D72:AH72,"A") -> 0 | AK72: =COUNTIF(D72:AH72,"CL") -> 0 | AL72: =COUNTIF(D72:AH72,"SL") -> 0 | AM72: =COUNTIF(D72:AH72,"EL") -> 0 | AN72: =COUNTIF(D72:AH72,"L") -> 0 | AO72: =COUNTIF(D72:AH72,"P")+COUNTIF(D72:AH72,"CL")+COUNTIF(D72:AH72,"SL")+COUNTIF(D72:AH72,"EL") -> 26 | AP72: =AO72/26*100 -> 100
A73: EMP072 | B73: =_xlfn.XLOOKUP(A73,Table1[Emp_ID],Table1[Full_Name ]) -> Meet | C73: =_xlfn.XLOOKUP(A73,Table1[Emp_ID],Table1[Department]) -> Support | D73: P | E73: P | F73: P | G73: SL | H73: H | I73: P | J73: P | K73: P | L73: L | M73: P | N73: P | O73: H | P73: H | Q73: P | R73: P | S73: P | T73: P | U73: P | V73: H | W73: P | X73: P | Y73: P | Z73: P | AA73: P | AB73: P | AC73: H | AD73: L | AE73: P | AF73: P | AG73: P | AH73: P | AI73: =COUNTIF(D73:AH73,"P") -> 23 | AJ73: =COUNTIF(D73:AH73,"A") -> 0 | AK73: =COUNTIF(D73:AH73,"CL") -> 0 | AL73: =COUNTIF(D73:AH73,"SL") -> 1 | AM73: =COUNTIF(D73:AH73,"EL") -> 0 | AN73: =COUNTIF(D73:AH73,"L") -> 2 | AO73: =COUNTIF(D73:AH73,"P")+COUNTIF(D73:AH73,"CL")+COUNTIF(D73:AH73,"SL")+COUNTIF(D73:AH73,"EL") -> 24 | AP73: =AO73/26*100 -> 92.307692
A74: EMP073 | B74: =_xlfn.XLOOKUP(A74,Table1[Emp_ID],Table1[Full_Name ]) -> Darshan | C74: =_xlfn.XLOOKUP(A74,Table1[Emp_ID],Table1[Department]) -> Support | D74: P | E74: P | F74: P | G74: P | H74: H | I74: P | J74: P | K74: P | L74: P | M74: P | N74: P | O74: H | P74: H | Q74: P | R74: P | S74: P | T74: P | U74: P | V74: H | W74: P | X74: A | Y74: P | Z74: P | AA74: P | AB74: P | AC74: H | AD74: P | AE74: P | AF74: P | AG74: P | AH74: P | AI74: =COUNTIF(D74:AH74,"P") -> 25 | AJ74: =COUNTIF(D74:AH74,"A") -> 1 | AK74: =COUNTIF(D74:AH74,"CL") -> 0 | AL74: =COUNTIF(D74:AH74,"SL") -> 0 | AM74: =COUNTIF(D74:AH74,"EL") -> 0 | AN74: =COUNTIF(D74:AH74,"L") -> 0 | AO74: =COUNTIF(D74:AH74,"P")+COUNTIF(D74:AH74,"CL")+COUNTIF(D74:AH74,"SL")+COUNTIF(D74:AH74,"EL") -> 25 | AP74: =AO74/26*100 -> 96.153846
A75: EMP074 | B75: =_xlfn.XLOOKUP(A75,Table1[Emp_ID],Table1[Full_Name ]) -> Jignesh | C75: =_xlfn.XLOOKUP(A75,Table1[Emp_ID],Table1[Department]) -> Support | D75: P | E75: P | F75: P | G75: P | H75: H | I75: P | J75: P | K75: P | L75: P | M75: A | N75: P | O75: H | P75: H | Q75: EL | R75: EL | S75: EL | T75: EL | U75: P | V75: H | W75: P | X75: P | Y75: P | Z75: P | AA75: P | AB75: P | AC75: H | AD75: P | AE75: P | AF75: CL | AG75: CL | AH75: P | AI75: =COUNTIF(D75:AH75,"P") -> 19 | AJ75: =COUNTIF(D75:AH75,"A") -> 1 | AK75: =COUNTIF(D75:AH75,"CL") -> 2 | AL75: =COUNTIF(D75:AH75,"SL") -> 0 | AM75: =COUNTIF(D75:AH75,"EL") -> 4 | AN75: =COUNTIF(D75:AH75,"L") -> 0 | AO75: =COUNTIF(D75:AH75,"P")+COUNTIF(D75:AH75,"CL")+COUNTIF(D75:AH75,"SL")+COUNTIF(D75:AH75,"EL") -> 25 | AP75: =AO75/26*100 -> 96.153846
A76: EMP075 | B76: =_xlfn.XLOOKUP(A76,Table1[Emp_ID],Table1[Full_Name ]) -> Hardik | C76: =_xlfn.XLOOKUP(A76,Table1[Emp_ID],Table1[Department]) -> Support | D76: P | E76: P | F76: P | G76: P | H76: H | I76: P | J76: P | K76: P | L76: P | M76: P | N76: P | O76: H | P76: H | Q76: P | R76: P | S76: P | T76: P | U76: P | V76: H | W76: P | X76: P | Y76: P | Z76: P | AA76: P | AB76: P | AC76: H | AD76: P | AE76: P | AF76: P | AG76: P | AH76: P | AI76: =COUNTIF(D76:AH76,"P") -> 26 | AJ76: =COUNTIF(D76:AH76,"A") -> 0 | AK76: =COUNTIF(D76:AH76,"CL") -> 0 | AL76: =COUNTIF(D76:AH76,"SL") -> 0 | AM76: =COUNTIF(D76:AH76,"EL") -> 0 | AN76: =COUNTIF(D76:AH76,"L") -> 0 | AO76: =COUNTIF(D76:AH76,"P")+COUNTIF(D76:AH76,"CL")+COUNTIF(D76:AH76,"SL")+COUNTIF(D76:AH76,"EL") -> 26 | AP76: =AO76/26*100 -> 100
A77: EMP076 | B77: =_xlfn.XLOOKUP(A77,Table1[Emp_ID],Table1[Full_Name ]) -> Hitesh | C77: =_xlfn.XLOOKUP(A77,Table1[Emp_ID],Table1[Department]) -> Support | D77: P | E77: P | F77: P | G77: P | H77: H | I77: P | J77: P | K77: P | L77: P | M77: P | N77: P | O77: H | P77: H | Q77: P | R77: P | S77: P | T77: P | U77: P | V77: H | W77: P | X77: P | Y77: P | Z77: P | AA77: P | AB77: P | AC77: H | AD77: P | AE77: A | AF77: P | AG77: P | AH77: P | AI77: =COUNTIF(D77:AH77,"P") -> 25 | AJ77: =COUNTIF(D77:AH77,"A") -> 1 | AK77: =COUNTIF(D77:AH77,"CL") -> 0 | AL77: =COUNTIF(D77:AH77,"SL") -> 0 | AM77: =COUNTIF(D77:AH77,"EL") -> 0 | AN77: =COUNTIF(D77:AH77,"L") -> 0 | AO77: =COUNTIF(D77:AH77,"P")+COUNTIF(D77:AH77,"CL")+COUNTIF(D77:AH77,"SL")+COUNTIF(D77:AH77,"EL") -> 25 | AP77: =AO77/26*100 -> 96.153846
A78: EMP077 | B78: =_xlfn.XLOOKUP(A78,Table1[Emp_ID],Table1[Full_Name ]) -> Paresh | C78: =_xlfn.XLOOKUP(A78,Table1[Emp_ID],Table1[Department]) -> Support | D78: A | E78: P | F78: P | G78: P | H78: H | I78: P | J78: P | K78: A | L78: P | M78: P | N78: P | O78: H | P78: H | Q78: P | R78: P | S78: P | T78: P | U78: P | V78: H | W78: P | X78: P | Y78: P | Z78: P | AA78: P | AB78: P | AC78: H | AD78: P | AE78: P | AF78: P | AG78: P | AH78: P | AI78: =COUNTIF(D78:AH78,"P") -> 24 | AJ78: =COUNTIF(D78:AH78,"A") -> 2 | AK78: =COUNTIF(D78:AH78,"CL") -> 0 | AL78: =COUNTIF(D78:AH78,"SL") -> 0 | AM78: =COUNTIF(D78:AH78,"EL") -> 0 | AN78: =COUNTIF(D78:AH78,"L") -> 0 | AO78: =COUNTIF(D78:AH78,"P")+COUNTIF(D78:AH78,"CL")+COUNTIF(D78:AH78,"SL")+COUNTIF(D78:AH78,"EL") -> 24 | AP78: =AO78/26*100 -> 92.307692
A79: EMP078 | B79: =_xlfn.XLOOKUP(A79,Table1[Emp_ID],Table1[Full_Name ]) -> Bhavesh | C79: =_xlfn.XLOOKUP(A79,Table1[Emp_ID],Table1[Department]) -> Support | D79: P | E79: P | F79: P | G79: P | H79: H | I79: P | J79: P | K79: P | L79: P | M79: P | N79: P | O79: H | P79: H | Q79: P | R79: P | S79: SL | T79: SL | U79: P | V79: H | W79: P | X79: P | Y79: P | Z79: P | AA79: P | AB79: P | AC79: H | AD79: P | AE79: P | AF79: P | AG79: P | AH79: P | AI79: =COUNTIF(D79:AH79,"P") -> 24 | AJ79: =COUNTIF(D79:AH79,"A") -> 0 | AK79: =COUNTIF(D79:AH79,"CL") -> 0 | AL79: =COUNTIF(D79:AH79,"SL") -> 2 | AM79: =COUNTIF(D79:AH79,"EL") -> 0 | AN79: =COUNTIF(D79:AH79,"L") -> 0 | AO79: =COUNTIF(D79:AH79,"P")+COUNTIF(D79:AH79,"CL")+COUNTIF(D79:AH79,"SL")+COUNTIF(D79:AH79,"EL") -> 26 | AP79: =AO79/26*100 -> 100
A80: EMP079 | B80: =_xlfn.XLOOKUP(A80,Table1[Emp_ID],Table1[Full_Name ]) -> Tushar | C80: =_xlfn.XLOOKUP(A80,Table1[Emp_ID],Table1[Department]) -> Support | D80: P | E80: P | F80: P | G80: P | H80: H | I80: P | J80: P | K80: P | L80: P | M80: P | N80: A | O80: H | P80: H | Q80: P | R80: P | S80: P | T80: P | U80: P | V80: H | W80: P | X80: P | Y80: P | Z80: P | AA80: P | AB80: P | AC80: H | AD80: P | AE80: P | AF80: P | AG80: P | AH80: P | AI80: =COUNTIF(D80:AH80,"P") -> 25 | AJ80: =COUNTIF(D80:AH80,"A") -> 1 | AK80: =COUNTIF(D80:AH80,"CL") -> 0 | AL80: =COUNTIF(D80:AH80,"SL") -> 0 | AM80: =COUNTIF(D80:AH80,"EL") -> 0 | AN80: =COUNTIF(D80:AH80,"L") -> 0 | AO80: =COUNTIF(D80:AH80,"P")+COUNTIF(D80:AH80,"CL")+COUNTIF(D80:AH80,"SL")+COUNTIF(D80:AH80,"EL") -> 25 | AP80: =AO80/26*100 -> 96.153846
A81: EMP080 | B81: =_xlfn.XLOOKUP(A81,Table1[Emp_ID],Table1[Full_Name ]) -> Chirag | C81: =_xlfn.XLOOKUP(A81,Table1[Emp_ID],Table1[Department]) -> Support | D81: P | E81: P | F81: L | G81: P | H81: H | I81: P | J81: P | K81: P | L81: P | M81: P | N81: P | O81: H | P81: H | Q81: P | R81: P | S81: P | T81: P | U81: P | V81: H | W81: P | X81: P | Y81: P | Z81: P | AC81: H | AD81: P | AE81: SL | AF81: P | AG81: P | AH81: P | AI81: =COUNTIF(D81:AH81,"P") -> 22 | AJ81: =COUNTIF(D81:AH81,"A") -> 0 | AK81: =COUNTIF(D81:AH81,"CL") -> 0 | AL81: =COUNTIF(D81:AH81,"SL") -> 1 | AM81: =COUNTIF(D81:AH81,"EL") -> 0 | AN81: =COUNTIF(D81:AH81,"L") -> 1 | AO81: =COUNTIF(D81:AH81,"P")+COUNTIF(D81:AH81,"CL")+COUNTIF(D81:AH81,"SL")+COUNTIF(D81:AH81,"EL") -> 23 | AP81: =AO81/26*100 -> 88.461538
A82: EMP081 | B82: =_xlfn.XLOOKUP(A82,Table1[Emp_ID],Table1[Full_Name ]) -> Nirav | C82: =_xlfn.XLOOKUP(A82,Table1[Emp_ID],Table1[Department]) -> Support | D82: P | E82: P | F82: P | G82: P | H82: H | I82: P | J82: P | K82: P | L82: L | M82: P | N82: P | O82: H | P82: H | Q82: P | R82: P | S82: P | T82: P | U82: P | V82: H | W82: P | X82: P | Y82: P | Z82: P | AA82: P | AB82: P | AC82: H | AD82: P | AE82: A | AF82: P | AG82: P | AH82: P | AI82: =COUNTIF(D82:AH82,"P") -> 24 | AJ82: =COUNTIF(D82:AH82,"A") -> 1 | AK82: =COUNTIF(D82:AH82,"CL") -> 0 | AL82: =COUNTIF(D82:AH82,"SL") -> 0 | AM82: =COUNTIF(D82:AH82,"EL") -> 0 | AN82: =COUNTIF(D82:AH82,"L") -> 1 | AO82: =COUNTIF(D82:AH82,"P")+COUNTIF(D82:AH82,"CL")+COUNTIF(D82:AH82,"SL")+COUNTIF(D82:AH82,"EL") -> 24 | AP82: =AO82/26*100 -> 92.307692
A83: EMP082 | B83: =_xlfn.XLOOKUP(A83,Table1[Emp_ID],Table1[Full_Name ]) -> Tejas | C83: =_xlfn.XLOOKUP(A83,Table1[Emp_ID],Table1[Department]) -> Support | D83: P | E83: P | F83: P | G83: A | H83: H | I83: P | J83: P | K83: P | L83: P | M83: P | N83: P | O83: H | P83: H | Q83: P | R83: P | S83: P | T83: P | U83: P | V83: H | W83: P | X83: P | Y83: P | Z83: P | AA83: P | AB83: P | AC83: H | AD83: P | AE83: P | AF83: P | AG83: P | AH83: P | AI83: =COUNTIF(D83:AH83,"P") -> 25 | AJ83: =COUNTIF(D83:AH83,"A") -> 1 | AK83: =COUNTIF(D83:AH83,"CL") -> 0 | AL83: =COUNTIF(D83:AH83,"SL") -> 0 | AM83: =COUNTIF(D83:AH83,"EL") -> 0 | AN83: =COUNTIF(D83:AH83,"L") -> 0 | AO83: =COUNTIF(D83:AH83,"P")+COUNTIF(D83:AH83,"CL")+COUNTIF(D83:AH83,"SL")+COUNTIF(D83:AH83,"EL") -> 25 | AP83: =AO83/26*100 -> 96.153846
A84: EMP083 | B84: =_xlfn.XLOOKUP(A84,Table1[Emp_ID],Table1[Full_Name ]) -> Vishal | C84: =_xlfn.XLOOKUP(A84,Table1[Emp_ID],Table1[Department]) -> Support | D84: P | E84: P | F84: P | G84: P | H84: H | I84: P | J84: P | K84: P | L84: P | M84: A | N84: P | O84: H | P84: H | Q84: P | R84: P | S84: P | T84: P | U84: P | V84: H | W84: P | X84: P | Y84: P | Z84: P | AA84: P | AB84: P | AC84: H | AD84: P | AE84: P | AF84: P | AG84: P | AH84: P | AI84: =COUNTIF(D84:AH84,"P") -> 25 | AJ84: =COUNTIF(D84:AH84,"A") -> 1 | AK84: =COUNTIF(D84:AH84,"CL") -> 0 | AL84: =COUNTIF(D84:AH84,"SL") -> 0 | AM84: =COUNTIF(D84:AH84,"EL") -> 0 | AN84: =COUNTIF(D84:AH84,"L") -> 0 | AO84: =COUNTIF(D84:AH84,"P")+COUNTIF(D84:AH84,"CL")+COUNTIF(D84:AH84,"SL")+COUNTIF(D84:AH84,"EL") -> 25 | AP84: =AO84/26*100 -> 96.153846
A85: EMP084 | B85: =_xlfn.XLOOKUP(A85,Table1[Emp_ID],Table1[Full_Name ]) -> Hemant | C85: =_xlfn.XLOOKUP(A85,Table1[Emp_ID],Table1[Department]) -> Support | D85: P | E85: P | F85: P | G85: P | H85: H | I85: P | J85: P | K85: P | L85: P | M85: P | N85: P | O85: H | P85: H | Q85: P | R85: P | S85: P | T85: A | U85: P | V85: H | W85: P | X85: P | Y85: P | Z85: P | AA85: P | AB85: P | AC85: H | AD85: P | AE85: P | AF85: P | AG85: P | AH85: P | AI85: =COUNTIF(D85:AH85,"P") -> 25 | AJ85: =COUNTIF(D85:AH85,"A") -> 1 | AK85: =COUNTIF(D85:AH85,"CL") -> 0 | AL85: =COUNTIF(D85:AH85,"SL") -> 0 | AM85: =COUNTIF(D85:AH85,"EL") -> 0 | AN85: =COUNTIF(D85:AH85,"L") -> 0 | AO85: =COUNTIF(D85:AH85,"P")+COUNTIF(D85:AH85,"CL")+COUNTIF(D85:AH85,"SL")+COUNTIF(D85:AH85,"EL") -> 25 | AP85: =AO85/26*100 -> 96.153846
A86: EMP085 | B86: =_xlfn.XLOOKUP(A86,Table1[Emp_ID],Table1[Full_Name ]) -> Lokesh | C86: =_xlfn.XLOOKUP(A86,Table1[Emp_ID],Table1[Department]) -> Support | D86: P | E86: A | F86: P | G86: P | H86: H | I86: P | J86: P | K86: P | L86: P | M86: P | N86: P | O86: H | P86: H | Q86: P | R86: P | S86: P | T86: P | U86: P | V86: H | W86: P | X86: L | Y86: P | Z86: P | AA86: P | AB86: P | AC86: H | AD86: SL | AE86: SL | AF86: P | AG86: P | AH86: P | AI86: =COUNTIF(D86:AH86,"P") -> 22 | AJ86: =COUNTIF(D86:AH86,"A") -> 1 | AK86: =COUNTIF(D86:AH86,"CL") -> 0 | AL86: =COUNTIF(D86:AH86,"SL") -> 2 | AM86: =COUNTIF(D86:AH86,"EL") -> 0 | AN86: =COUNTIF(D86:AH86,"L") -> 1 | AO86: =COUNTIF(D86:AH86,"P")+COUNTIF(D86:AH86,"CL")+COUNTIF(D86:AH86,"SL")+COUNTIF(D86:AH86,"EL") -> 24 | AP86: =AO86/26*100 -> 92.307692
A87: EMP086 | B87: =_xlfn.XLOOKUP(A87,Table1[Emp_ID],Table1[Full_Name ]) -> Dinesh | C87: =_xlfn.XLOOKUP(A87,Table1[Emp_ID],Table1[Department]) -> Support | D87: P | E87: P | F87: P | G87: P | H87: H | I87: P | J87: P | K87: A | L87: P | M87: P | N87: P | O87: H | P87: H | Q87: P | R87: L | S87: P | T87: P | U87: P | V87: H | W87: P | X87: P | Y87: P | Z87: P | AA87: P | AB87: P | AC87: H | AD87: P | AE87: P | AF87: P | AG87: P | AH87: P | AI87: =COUNTIF(D87:AH87,"P") -> 24 | AJ87: =COUNTIF(D87:AH87,"A") -> 1 | AK87: =COUNTIF(D87:AH87,"CL") -> 0 | AL87: =COUNTIF(D87:AH87,"SL") -> 0 | AM87: =COUNTIF(D87:AH87,"EL") -> 0 | AN87: =COUNTIF(D87:AH87,"L") -> 1 | AO87: =COUNTIF(D87:AH87,"P")+COUNTIF(D87:AH87,"CL")+COUNTIF(D87:AH87,"SL")+COUNTIF(D87:AH87,"EL") -> 24 | AP87: =AO87/26*100 -> 92.307692
A88: EMP087 | B88: =_xlfn.XLOOKUP(A88,Table1[Emp_ID],Table1[Full_Name ]) -> Umesh | C88: =_xlfn.XLOOKUP(A88,Table1[Emp_ID],Table1[Department]) -> Accounts | D88: P | E88: P | F88: P | G88: P | H88: H | I88: P | J88: P | K88: P | L88: P | M88: P | N88: P | O88: H | P88: H | Q88: P | R88: P | S88: P | T88: P | U88: P | V88: H | W88: P | X88: P | Y88: P | Z88: P | AA88: P | AB88: P | AC88: H | AD88: P | AE88: P | AF88: P | AG88: P | AH88: P | AI88: =COUNTIF(D88:AH88,"P") -> 26 | AJ88: =COUNTIF(D88:AH88,"A") -> 0 | AK88: =COUNTIF(D88:AH88,"CL") -> 0 | AL88: =COUNTIF(D88:AH88,"SL") -> 0 | AM88: =COUNTIF(D88:AH88,"EL") -> 0 | AN88: =COUNTIF(D88:AH88,"L") -> 0 | AO88: =COUNTIF(D88:AH88,"P")+COUNTIF(D88:AH88,"CL")+COUNTIF(D88:AH88,"SL")+COUNTIF(D88:AH88,"EL") -> 26 | AP88: =AO88/26*100 -> 100
A89: EMP088 | B89: =_xlfn.XLOOKUP(A89,Table1[Emp_ID],Table1[Full_Name ]) -> Naresh | C89: =_xlfn.XLOOKUP(A89,Table1[Emp_ID],Table1[Department]) -> Accounts | D89: P | E89: P | F89: P | G89: P | H89: H | I89: P | J89: P | K89: P | L89: P | M89: P | N89: P | O89: H | P89: H | Q89: P | R89: P | S89: A | T89: P | U89: P | V89: H | W89: P | X89: P | Y89: CL | Z89: CL | AA89: P | AB89: P | AC89: H | AD89: P | AE89: P | AF89: P | AG89: P | AH89: P | AI89: =COUNTIF(D89:AH89,"P") -> 23 | AJ89: =COUNTIF(D89:AH89,"A") -> 1 | AK89: =COUNTIF(D89:AH89,"CL") -> 2 | AL89: =COUNTIF(D89:AH89,"SL") -> 0 | AM89: =COUNTIF(D89:AH89,"EL") -> 0 | AN89: =COUNTIF(D89:AH89,"L") -> 0 | AO89: =COUNTIF(D89:AH89,"P")+COUNTIF(D89:AH89,"CL")+COUNTIF(D89:AH89,"SL")+COUNTIF(D89:AH89,"EL") -> 25 | AP89: =AO89/26*100 -> 96.153846
A90: EMP089 | B90: =_xlfn.XLOOKUP(A90,Table1[Emp_ID],Table1[Full_Name ]) -> Rajiv | C90: =_xlfn.XLOOKUP(A90,Table1[Emp_ID],Table1[Department]) -> Accounts | D90: P | E90: P | F90: L | G90: P | H90: H | I90: P | J90: P | K90: P | L90: P | M90: P | N90: P | O90: H | P90: H | Q90: P | R90: P | S90: P | T90: P | U90: P | V90: H | W90: P | X90: P | Y90: P | Z90: P | AA90: P | AB90: P | AC90: H | AD90: P | AE90: P | AF90: P | AG90: P | AH90: P | AI90: =COUNTIF(D90:AH90,"P") -> 25 | AJ90: =COUNTIF(D90:AH90,"A") -> 0 | AK90: =COUNTIF(D90:AH90,"CL") -> 0 | AL90: =COUNTIF(D90:AH90,"SL") -> 0 | AM90: =COUNTIF(D90:AH90,"EL") -> 0 | AN90: =COUNTIF(D90:AH90,"L") -> 1 | AO90: =COUNTIF(D90:AH90,"P")+COUNTIF(D90:AH90,"CL")+COUNTIF(D90:AH90,"SL")+COUNTIF(D90:AH90,"EL") -> 25 | AP90: =AO90/26*100 -> 96.153846
A91: EMP090 | B91: =_xlfn.XLOOKUP(A91,Table1[Emp_ID],Table1[Full_Name ]) -> Suresh | C91: =_xlfn.XLOOKUP(A91,Table1[Emp_ID],Table1[Department]) -> Accounts | D91: P | E91: P | F91: P | G91: P | H91: H | I91: P | J91: P | K91: P | L91: P | M91: P | N91: P | O91: H | P91: H | Q91: P | R91: P | S91: P | T91: P | U91: P | V91: H | W91: P | X91: A | Y91: P | Z91: P | AA91: P | AB91: P | AC91: H | AD91: P | AE91: EL | AF91: EL | AG91: EL | AH91: EL | AI91: =COUNTIF(D91:AH91,"P") -> 21 | AJ91: =COUNTIF(D91:AH91,"A") -> 1 | AK91: =COUNTIF(D91:AH91,"CL") -> 0 | AL91: =COUNTIF(D91:AH91,"SL") -> 0 | AM91: =COUNTIF(D91:AH91,"EL") -> 4 | AN91: =COUNTIF(D91:AH91,"L") -> 0 | AO91: =COUNTIF(D91:AH91,"P")+COUNTIF(D91:AH91,"CL")+COUNTIF(D91:AH91,"SL")+COUNTIF(D91:AH91,"EL") -> 25 | AP91: =AO91/26*100 -> 96.153846
A92: EMP091 | B92: =_xlfn.XLOOKUP(A92,Table1[Emp_ID],Table1[Full_Name ]) -> Girish | C92: =_xlfn.XLOOKUP(A92,Table1[Emp_ID],Table1[Department]) -> Accounts | D92: P | E92: P | F92: P | G92: A | H92: H | I92: P | J92: P | K92: P | L92: P | M92: P | N92: P | O92: H | P92: H | Q92: A | R92: P | S92: P | T92: P | U92: P | V92: H | W92: P | X92: P | Y92: P | Z92: P | AA92: P | AB92: P | AC92: H | AD92: P | AE92: P | AF92: P | AG92: P | AH92: P | AI92: =COUNTIF(D92:AH92,"P") -> 24 | AJ92: =COUNTIF(D92:AH92,"A") -> 2 | AK92: =COUNTIF(D92:AH92,"CL") -> 0 | AL92: =COUNTIF(D92:AH92,"SL") -> 0 | AM92: =COUNTIF(D92:AH92,"EL") -> 0 | AN92: =COUNTIF(D92:AH92,"L") -> 0 | AO92: =COUNTIF(D92:AH92,"P")+COUNTIF(D92:AH92,"CL")+COUNTIF(D92:AH92,"SL")+COUNTIF(D92:AH92,"EL") -> 24 | AP92: =AO92/26*100 -> 92.307692
...

Sheet PAYROLL
A1: Emp_ID | B1: Emp_Name | C1: Department | D1: Designation | E1: Basic_Salary | F1: HRA | G1: DA | H1: Gross_Salary | I1: PF | J1: ESI | K1: Prof_Tax | L1: LOP_Deduction | M1: Total_Deductions | N1: Net_Salary | O1: Salary_Status
A2: EMP001 | B2: =_xlfn.XLOOKUP(Table3[[#This Row],[Emp_ID]],Table1[Emp_ID],Table1[Full_Name ]) -> Aarav | C2: =_xlfn.XLOOKUP(Table3[[#This Row],[Emp_ID]],Table1[Emp_ID],Table1[Department]) -> Operations | D2: =_xlfn.XLOOKUP(Table3[[#This Row],[Emp_ID]],Table1[Emp_ID],Table1[Designation]) -> Associate / Operator | E2: =_xlfn.XLOOKUP(Table3[[#This Row],[Emp_ID]],Table1[Emp_ID],Table1[Basic_Salary]) -> 12000 | F2: =E2*_xlfn.XLOOKUP(Table3[[#This Row],[Emp_ID]],Table1[Emp_ID],Table1[HRA_%]) -> 2400 | G2: =E2*_xlfn.XLOOKUP(Table3[[#This Row],[Emp_ID]],Table1[Emp_ID],Table1[DA_%]) -> 960 | H2: =E2+F2+G2 -> 15360 | I2: =IF(E2>15000,ROUND(E2*0.12,0),0) -> 0 | J2: =IF(H2<21000,ROUND(H2*0.0075,0),0) -> 115 | K2: =IF(H2<=10000,0,IF(H2<=15000,150,IF(H2<=25000,300,200))) -> 300 | L2: =ROUND((E2/26)*_xlfn.XLOOKUP(Table3[[#This Row],[Emp_ID]],Table2[Emp_ID],Table2[Total Absent]),0) -> 462 | M2: =I2+J2+K2+L2 -> 877 | N2: =H2-M2 -> 14483 | O2: =IF(N2>=30000,"High",IF(N2>=20000,"Mid",IF(N2>=12000,"Low","Review"))) -> Low
A3: EMP002 | B3: =_xlfn.XLOOKUP(Table3[[#This Row],[Emp_ID]],Table1[Emp_ID],Table1[Full_Name ]) -> Vivaan | C3: =_xlfn.XLOOKUP(Table3[[#This Row],[Emp_ID]],Table1[Emp_ID],Table1[Department]) -> Operations | D3: =_xlfn.XLOOKUP(Table3[[#This Row],[Emp_ID]],Table1[Emp_ID],Table1[Designation]) -> Associate / Operator | E3: =_xlfn.XLOOKUP(Table3[[#This Row],[Emp_ID]],Table1[Emp_ID],Table1[Basic_Salary]) -> 13000 | F3: =E3*_xlfn.XLOOKUP(Table3[[#This Row],[Emp_ID]],Table1[Emp_ID],Table1[HRA_%]) -> 2600 | G3: =E3*_xlfn.XLOOKUP(Table3[[#This Row],[Emp_ID]],Table1[Emp_ID],Table1[DA_%]) -> 1040 | H3: =E3+F3+G3 -> 16640 | I3: =IF(E3>15000,ROUND(E3*0.12,0),0) -> 0 | J3: =IF(H3<21000,ROUND(H3*0.0075,0),0) -> 125 | K3: =IF(H3<=10000,0,IF(H3<=15000,150,IF(H3<=25000,300,200))) -> 300 | L3: =ROUND((E3/26)*_xlfn.XLOOKUP(Table3[[#This Row],[Emp_ID]],Table2[Emp_ID],Table2[Total Absent]),0) -> 500 | M3: =I3+J3+K3+L3 -> 925 | N3: =H3-M3 -> 15715 | O3: =IF(N3>=30000,"High",IF(N3>=20000,"Mid",IF(N3>=12000,"Low","Review"))) -> Low
A4: EMP003 | B4: =_xlfn.XLOOKUP(Table3[[#This Row],[Emp_ID]],Table1[Emp_ID],Table1[Full_Name ]) -> Aditya | C4: =_xlfn.XLOOKUP(Table3[[#This Row],[Emp_ID]],Table1[Emp_ID],Table1[Department]) -> Operations | D4: =_xlfn.XLOOKUP(Table3[[#This Row],[Emp_ID]],Table1[Emp_ID],Table1[Designation]) -> Associate / Operator | E4: =_xlfn.XLOOKUP(Table3[[#This Row],[Emp_ID]],Table1[Emp_ID],Table1[Basic_Salary]) -> 13500 | F4: =E4*_xlfn.XLOOKUP(Table3[[#This Row],[Emp_ID]],Table1[Emp_ID],Table1[HRA_%]) -> 2700 | G4: =E4*_xlfn.XLOOKUP(Table3[[#This Row],[Emp_ID]],Table1[Emp_ID],Table1[DA_%]) -> 1080 | H4: =E4+F4+G4 -> 17280 | I4: =IF(E4>15000,ROUND(E4*0.12,0),0) -> 0 | J4: =IF(H4<21000,ROUND(H4*0.0075,0),0) -> 130 | K4: =IF(H4<=10000,0,IF(H4<=15000,150,IF(H4<=25000,300,200))) -> 300 | L4: =ROUND((E4/26)*_xlfn.XLOOKUP(Table3[[#This Row],[Emp_ID]],Table2[Emp_ID],Table2[Total Absent]),0) -> 0 | M4: =I4+J4+K4+L4 -> 430 | N4: =H4-M4 -> 16850 | O4: =IF(N4>=30000,"High",IF(N4>=20000,"Mid",IF(N4>=12000,"Low","Review"))) -> Low
A5: EMP004 | B5: =_xlfn.XLOOKUP(Table3[[#This Row],[Emp_ID]],Table1[Emp_ID],Table1[Full_Name ]) -> Arjun | C5: =_xlfn.XLOOKUP(Table3[[#This Row],[Emp_ID]],Table1[Emp_ID],Table1[Department]) -> Operations | D5: =_xlfn.XLOOKUP(Table3[[#This Row],[Emp_ID]],Table1[Emp_ID],Table1[Designation]) -> Associate / Operator | E5: =_xlfn.XLOOKUP(Table3[[#This Row],[Emp_ID]],Table1[Emp_ID],Table1[Basic_Salary]) -> 15000 | F5: =E5*_xlfn.XLOOKUP(Table3[[#This Row],[Emp_ID]],Table1[Emp_ID],Table1[HRA_%]) -> 3000 | G5: =E5*_xlfn.XLOOKUP(Table3[[#This Row],[Emp_ID]],Table1[Emp_ID],Table1[DA_%]) -> 1200 | H5: =E5+F5+G5 -> 19200 | I5: =IF(E5>15000,ROUND(E5*0.12,0),0) -> 0 | J5: =IF(H5<21000,ROUND(H5*0.0075,0),0) -> 144 | K5: =IF(H5<=10000,0,IF(H5<=15000,150,IF(H5<=25000,300,200))) -> 300 | L5: =ROUND((E5/26)*_xlfn.XLOOKUP(Table3[[#This Row],[Emp_ID]],Table2[Emp_ID],Table2[Total Absent]),0) -> 577 | M5: =I5+J5+K5+L5 -> 1021 | N5: =H5-M5 -> 18179 | O5: =IF(N5>=30000,"High",IF(N5>=20000,"Mid",IF(N5>=12000,"Low","Review"))) -> Low
A6: EMP005 | B6: =_xlfn.XLOOKUP(Table3[[#This Row],[Emp_ID]],Table1[Emp_ID],Table1[Full_Name ]) -> Reyansh | C6: =_xlfn.XLOOKUP(Table3[[#This Row],[Emp_ID]],Table1[Emp_ID],Table1[Department]) -> Operations | D6: =_xlfn.XLOOKUP(Table3[[#This Row],[Emp_ID]],Table1[Emp_ID],Table1[Designation]) -> Executive | E6: =_xlfn.XLOOKUP(Table3[[#This Row],[Emp_ID]],Table1[Emp_ID],Table1[Basic_Salary]) -> 27000 | F6: =E6*_xlfn.XLOOKUP(Table3[[#This Row],[Emp_ID]],Table1[Emp_ID],Table1[HRA_%]) -> 8100 | G6: =E6*_xlfn.XLOOKUP(Table3[[#This Row],[Emp_ID]],Table1[Emp_ID],Table1[DA_%]) -> 2700 | H6: =E6+F6+G6 -> 37800 | I6: =IF(E6>15000,ROUND(E6*0.12,0),0) -> 3240 | J6: =IF(H6<21000,ROUND(H6*0.0075,0),0) -> 0 | K6: =IF(H6<=10000,0,IF(H6<=15000,150,IF(H6<=25000,300,200))) -> 200 | L6: =ROUND((E6/26)*_xlfn.XLOOKUP(Table3[[#This Row],[Emp_ID]],Table2[Emp_ID],Table2[Total Absent]),0) -> 1038 | M6: =I6+J6+K6+L6 -> 4478 | N6: =H6-M6 -> 33322 | O6: =IF(N6>=30000,"High",IF(N6>=20000,"Mid",IF(N6>=12000,"Low","Review"))) -> High
A7: EMP006 | B7: =_xlfn.XLOOKUP(Table3[[#This Row],[Emp_ID]],Table1[Emp_ID],Table1[Full_Name ]) -> Muhammad | C7: =_xlfn.XLOOKUP(Table3[[#This Row],[Emp_ID]],Table1[Emp_ID],Table1[Department]) -> Operations | D7: =_xlfn.XLOOKUP(Table3[[#This Row],[Emp_ID]],Table1[Emp_ID],Table1[Designation]) -> Associate / Operator | E7: =_xlfn.XLOOKUP(Table3[[#This Row],[Emp_ID]],Table1[Emp_ID],Table1[Basic_Salary]) -> 17000 | F7: =E7*_xlfn.XLOOKUP(Table3[[#This Row],[Emp_ID]],Table1[Emp_ID],Table1[HRA_%]) -> 3400 | G7: =E7*_xlfn.XLOOKUP(Table3[[#This Row],[Emp_ID]],Table1[Emp_ID],Table1[DA_%]) -> 1360 | H7: =E7+F7+G7 -> 21760 | I7: =IF(E7>15000,ROUND(E7*0.12,0),0) -> 2040 | J7: =IF(H7<21000,ROUND(H7*0.0075,0),0) -> 0 | K7: =IF(H7<=10000,0,IF(H7<=15000,150,IF(H7<=25000,300,200))) -> 300 | L7: =ROUND((E7/26)*_xlfn.XLOOKUP(Table3[[#This Row],[Emp_ID]],Table2[Emp_ID],Table2[Total Absent]),0) -> 0 | M7: =I7+J7+K7+L7 -> 2340 | N7: =H7-M7 -> 19420 | O7: =IF(N7>=30000,"High",IF(N7>=20000,"Mid",IF(N7>=12000,"Low","Review"))) -> Low
A8: EMP007 | B8: =_xlfn.XLOOKUP(Table3[[#This Row],[Emp_ID]],Table1[Emp_ID],Table1[Full_Name ]) -> Krishna | C8: =_xlfn.XLOOKUP(Table3[[#This Row],[Emp_ID]],Table1[Emp_ID],Table1[Department]) -> Operations | D8: =_xlfn.XLOOKUP(Table3[[#This Row],[Emp_ID]],Table1[Emp_ID],Table1[Designation]) -> Associate / Operator | E8: =_xlfn.XLOOKUP(Table3[[#This Row],[Emp_ID]],Table1[Emp_ID],Table1[Basic_Salary]) -> 15000 | F8: =E8*_xlfn.XLOOKUP(Table3[[#This Row],[Emp_ID]],Table1[Emp_ID],Table1[HRA_%]) -> 3000 | G8: =E8*_xlfn.XLOOKUP(Table3[[#This Row],[Emp_ID]],Table1[Emp_ID],Table1[DA_%]) -> 1200 | H8: =E8+F8+G8 -> 19200 | I8: =IF(E8>15000,ROUND(E8*0.12,0),0) -> 0 | J8: =IF(H8<21000,ROUND(H8*0.0075,0),0) -> 144 | K8: =IF(H8<=10000,0,IF(H8<=15000,150,IF(H8<=25000,300,200))) -> 300 | L8: =ROUND((E8/26)*_xlfn.XLOOKUP(Table3[[#This Row],[Emp_ID]],Table2[Emp_ID],Table2[Total Absent]),0) -> 577 | M8: =I8+J8+K8+L8 -> 1021 | N8: =H8-M8 -> 18179 | O8: =IF(N8>=30000,"High",IF(N8>=20000,"Mid",IF(N8>=12000,"Low","Review"))) -> Low
A9: EMP008 | B9: =_xlfn.XLOOKUP(Table3[[#This Row],[Emp_ID]],Table1[Emp_ID],Table1[Full_Name ]) -> Ishaan | C9: =_xlfn.XLOOKUP(Table3[[#This Row],[Emp_ID]],Table1[Emp_ID],Table1[Department]) -> Operations | D9: =_xlfn.XLOOKUP(Table3[[#This Row],[Emp_ID]],Table1[Emp_ID],Table1[Designation]) -> Associate / Operator | E9: =_xlfn.XLOOKUP(Table3[[#This Row],[Emp_ID]],Table1[Emp_ID],Table1[Basic_Salary]) -> 14000 | F9: =E9*_xlfn.XLOOKUP(Table3[[#This Row],[Emp_ID]],Table1[Emp_ID],Table1[HRA_%]) -> 2800 | G9: =E9*_xlfn.XLOOKUP(Table3[[#This Row],[Emp_ID]],Table1[Emp_ID],Table1[DA_%]) -> 1120 | H9: =E9+F9+G9 -> 17920 | I9: =IF(E9>15000,ROUND(E9*0.12,0),0) -> 0 | J9: =IF(H9<21000,ROUND(H9*0.0075,0),0) -> 134 | K9: =IF(H9<=10000,0,IF(H9<=15000,150,IF(H9<=25000,300,200))) -> 300 | L9: =ROUND((E9/26)*_xlfn.XLOOKUP(Table3[[#This Row],[Emp_ID]],Table2[Emp_ID],Table2[Total Absent]),0) -> 538 | M9: =I9+J9+K9+L9 -> 972 | N9: =H9-M9 -> 16948 | O9: =IF(N9>=30000,"High",IF(N9>=20000,"Mid",IF(N9>=12000,"Low","Review"))) -> Low
A10: EMP009 | B10: =_xlfn.XLOOKUP(Table3[[#This Row],[Emp_ID]],Table1[Emp_ID],Table1[Full_Name ]) -> Shaurya | C10: =_xlfn.XLOOKUP(Table3[[#This Row],[Emp_ID]],Table1[Emp_ID],Table1[Department]) -> Operations | D10: =_xlfn.XLOOKUP(Table3[[#This Row],[Emp_ID]],Table1[Emp_ID],Table1[Designation]) -> Executive | E10: =_xlfn.XLOOKUP(Table3[[#This Row],[Emp_ID]],Table1[Emp_ID],Table1[Basic_Salary]) -> 23000 | F10: =E10*_xlfn.XLOOKUP(Table3[[#This Row],[Emp_ID]],Table1[Emp_ID],Table1[HRA_%]) -> 6900 | G10: =E10*_xlfn.XLOOKUP(Table3[[#This Row],[Emp_ID]],Table1[Emp_ID],Table1[DA_%]) -> 2300 | H10: =E10+F10+G10 -> 32200 | I10: =IF(E10>15000,ROUND(E10*0.12,0),0) -> 2760 | J10: =IF(H10<21000,ROUND(H10*0.0075,0),0) -> 0 | K10: =IF(H10<=10000,0,IF(H10<=15000,150,IF(H10<=25000,300,200))) -> 200 | L10: =ROUND((E10/26)*_xlfn.XLOOKUP(Table3[[#This Row],[Emp_ID]],Table2[Emp_ID],Table2[Total Absent]),0) -> 0 | M10: =I10+J10+K10+L10 -> 2960 | N10: =H10-M10 -> 29240 | O10: =IF(N10>=30000,"High",IF(N10>=20000,"Mid",IF(N10>=12000,"Low","Review"))) -> Mid
A11: EMP010 | B11: =_xlfn.XLOOKUP(Table3[[#This Row],[Emp_ID]],Table1[Emp_ID],Table1[Full_Name ]) -> Atharv | C11: =_xlfn.XLOOKUP(Table3[[#This Row],[Emp_ID]],Table1[Emp_ID],Table1[Department]) -> Operations | D11: =_xlfn.XLOOKUP(Table3[[#This Row],[Emp_ID]],Table1[Emp_ID],Table1[Designation]) -> Associate / Operator | E11: =_xlfn.XLOOKUP(Table3[[#This Row],[Emp_ID]],Table1[Emp_ID],Table1[Basic_Salary]) -> 14000 | F11: =E11*_xlfn.XLOOKUP(Table3[[#This Row],[Emp_ID]],Table1[Emp_ID],Table1[HRA_%]) -> 2800 | G11: =E11*_xlfn.XLOOKUP(Table3[[#This Row],[Emp_ID]],Table1[Emp_ID],Table1[DA_%]) -> 1120 | H11: =E11+F11+G11 -> 17920 | I11: =IF(E11>15000,ROUND(E11*0.12,0),0) -> 0 | J11: =IF(H11<21000,ROUND(H11*0.0075,0),0) -> 134 | K11: =IF(H11<=10000,0,IF(H11<=15000,150,IF(H11<=25000,300,200))) -> 300 | L11: =ROUND((E11/26)*_xlfn.XLOOKUP(Table3[[#This Row],[Emp_ID]],Table2[Emp_ID],Table2[Total Absent]),0) -> 538 | M11: =I11+J11+K11+L11 -> 972 | N11: =H11-M11 -> 16948 | O11: =IF(N11>=30000,"High",IF(N11>=20000,"Mid",IF(N11>=12000,"Low","Review"))) -> Low
A12: EMP011 | B12: =_xlfn.XLOOKUP(Table3[[#This Row],[Emp_ID]],Table1[Emp_ID],Table1[Full_Name ]) -> Kabir | C12: =_xlfn.XLOOKUP(Table3[[#This Row],[Emp_ID]],Table1[Emp_ID],Table1[Department]) -> Operations | D12: =_xlfn.XLOOKUP(Table3[[#This Row],[Emp_ID]],Table1[Emp_ID],Table1[Designation]) -> Manager | E12: =_xlfn.XLOOKUP(Table3[[#This Row],[Emp_ID]],Table1[Emp_ID],Table1[Basic_Salary]) -> 55000 | F12: =E12*_xlfn.XLOOKUP(Table3[[#This Row],[Emp_ID]],Table1[Emp_ID],Table1[HRA_%]) -> 22000 | G12: =E12*_xlfn.XLOOKUP(Table3[[#This Row],[Emp_ID]],Table1[Emp_ID],Table1[DA_%]) -> 8250 | H12: =E12+F12+G12 -> 85250 | I12: =IF(E12>15000,ROUND(E12*0.12,0),0) -> 6600 | J12: =IF(H12<21000,ROUND(H12*0.0075,0),0) -> 0 | K12: =IF(H12<=10000,0,IF(H12<=15000,150,IF(H12<=25000,300,200))) -> 200 | L12: =ROUND((E12/26)*_xlfn.XLOOKUP(Table3[[#This Row],[Emp_ID]],Table2[Emp_ID],Table2[Total Absent]),0) -> 2115 | M12: =I12+J12+K12+L12 -> 8915 | N12: =H12-M12 -> 76335 | O12: =IF(N12>=30000,"High",IF(N12>=20000,"Mid",IF(N12>=12000,"Low","Review"))) -> High
A13: EMP012 | B13: =_xlfn.XLOOKUP(Table3[[#This Row],[Emp_ID]],Table1[Emp_ID],Table1[Full_Name ]) -> Rohan | C13: =_xlfn.XLOOKUP(Table3[[#This Row],[Emp_ID]],Table1[Emp_ID],Table1[Department]) -> Operations | D13: =_xlfn.XLOOKUP(Table3[[#This Row],[Emp_ID]],Table1[Emp_ID],Table1[Designation]) -> Associate / Operator | E13: =_xlfn.XLOOKUP(Table3[[#This Row],[Emp_ID]],Table1[Emp_ID],Table1[Basic_Salary]) -> 18000 | F13: =E13*_xlfn.XLOOKUP(Table3[[#This Row],[Emp_ID]],Table1[Emp_ID],Table1[HRA_%]) -> 3600 | G13: =E13*_xlfn.XLOOKUP(Table3[[#This Row],[Emp_ID]],Table1[Emp_ID],Table1[DA_%]) -> 1440 | H13: =E13+F13+G13 -> 23040 | I13: =IF(E13>15000,ROUND(E13*0.12,0),0) -> 2160 | J13: =IF(H13<21000,ROUND(H13*0.0075,0),0) -> 0 | K13: =IF(H13<=10000,0,IF(H13<=15000,150,IF(H13<=25000,300,200))) -> 300 | L13: =ROUND((E13/26)*_xlfn.XLOOKUP(Table3[[#This Row],[Emp_ID]],Table2[Emp_ID],Table2[Total Absent]),0) -> 0 | M13: =I13+J13+K13+L13 -> 2460 | N13: =H13-M13 -> 20580 | O13: =IF(N13>=30000,"High",IF(N13>=20000,"Mid",IF(N13>=12000,"Low","Review"))) -> Mid
... A107: EMP106 | B107: =_xlfn.XLOOKUP(Table3[[#This Row],[Emp_ID]],Table1[Emp_ID],Table1[Full_Name ]) -> Jagdish | C107: =_xlfn.XLOOKUP(Table3[[#This Row],[Emp_ID]],Table1[Emp_ID],Table1[Department]) -> IT | D107: =_xlfn.XLOOKUP(Table3[[#This Row],[Emp_ID]],Table1[Emp_ID],Table1[Designation]) -> Executive | E107: =_xlfn.XLOOKUP(Table3[[#This Row],[Emp_ID]],Table1[Emp_ID],Table1[Basic_Salary]) -> 26000 | F107: =E107*_xlfn.XLOOKUP(Table3[[#This Row],[Emp_ID]],Table1[Emp_ID],Table1[HRA_%]) -> 7800 | G107: =E107*_xlfn.XLOOKUP(Table3[[#This Row],[Emp_ID]],Table1[Emp_ID],Table1[DA_%]) -> 2600 | H107: =E107+F107+G107 -> 36400 | I107: =IF(E107>15000,ROUND(E107*0.12,0),0) -> 3120 | J107: =IF(H107<21000,ROUND(H107*0.0075,0),0) -> 0 | K107: =IF(H107<=10000,0,IF(H107<=15000,150,IF(H107<=25000,300,200))) -> 200 | L107: =ROUND((E107/26)*_xlfn.XLOOKUP(Table3[[#This Row],[Emp_ID]],Table2[Emp_ID],Table2[Total Absent]),0) -> 0 | M107: =I107+J107+K107+L107 -> 3320 | N107: =H107-M107 -> 33080 | O107: =IF(N107>=30000,"High",IF(N107>=20000,"Mid",IF(N107>=12000,"Low","Review"))) -> High
A110: Total Payroll Cost | B110: =SUM(N2:N107) -> 3027802
A111: Avg Net Salary | B111: =AVERAGE(N2:N107) -> 28564.17
A112: Highest Salary | B112: =MAX(N2:N107) -> 85600
A113: Lowest Salary | B113: =MIN(N2:N107) -> 14483
A114: Total PF Deducted | B114: =SUM(I2:I107) -> 227820
A115: Total ESI Deducted | B115: =SUM(J2:J107) -> 6303
A116: Total LOP Deducted | B116: =SUM(L2:L107) -> 64975 | G116: =AVERAGEIF(Attendance!C$2:C$107,"Operations",Attendance!AP$2:AP$107) -> 97.086247
A117: Department | B117: Total Net Salary | C117: Avg Net Salary | D117: Headcount
A118: Operations | B118: =SUMIF(C$2:C$107,A118,N$2:N$107) -> 806749 | C118: =AVERAGEIF(C$2:C$107,$A118,N$2:N$107) -> 24446.939 | D118: =COUNTIF(C$2:C$107,$A118) -> 33
A119: Warehouse | B119: =SUMIF(C$2:C$107,A119,N$2:N$107) -> 546004 | C119: =AVERAGEIF(C$2:C$107,$A119,N$2:N$107) -> 26000.19 | D119: =COUNTIF(C$2:C$107,$A119) -> 21
A120: Marketing | B120: =SUMIF(C$2:C$107,A120,N$2:N$107) -> 481241 | C120: =AVERAGEIF(C$2:C$107,$A120,N$2:N$107) -> 30077.562 | D120: =COUNTIF(C$2:C$107,$A120) -> 16
A121: Support | B121: =SUMIF(C$2:C$107,A121,N$2:N$107) -> 452887 | C121: =AVERAGEIF(C$2:C$107,$A121,N$2:N$107) -> 28305.438 | D121: =COUNTIF(C$2:C$107,$A121) -> 16
A122: Accounts | B122: =SUMIF(C$2:C$107,A122,N$2:N$107) -> 203124 | C122: =AVERAGEIF(C$2:C$107,$A122,N$2:N$107) -> 33854 | D122: =COUNTIF(C$2:C$107,$A122) -> 6
A123: IT | B123: =SUMIF(C$2:C$107,A123,N$2:N$107) -> 306688 | C123: =AVERAGEIF(C$2:C$107,$A123,N$2:N$107) -> 38336 | D123: =COUNTIF(C$2:C$107,$A123) -> 8
A124: HR | B124: =SUMIF(C$2:C$107,A124,N$2:N$107) -> 231109 | C124: =AVERAGEIF(C$2:C$107,$A124,N$2:N$107) -> 38518.167 | D124: =COUNTIF(C$2:C$107,$A124) -> 6

Sheet DASHBOARD
A1: HR & Payroll MIS Dashboard | January 2025
A3: S.S. Enterprises | 106 Employees | Reporting Period: Jan 2025
B5: =PAYROLL!B110 -> 3027802 | K5: =PAYROLL!B111 -> 28564.17 | T5: =AVERAGE(Attendance!AP2:AP107) -> 96.335269 | AC5: =SUM(Attendance!AJ2:AJ107) -> 79
B9: Total Payroll Cost | K9: Avg Net Salary | T9: Avg Attendance % | AC9: Total Absences
R37: Data Source: EMP_MASTER | ATTENDANCE | PAYROLL Last Updated: January 2025
AO42: Status | AP42: Count
AO43: Hight | AP43: =COUNTIF(PAYROLL!O2:O107,"High") -> 35
AO44: Mid | AP44: =COUNTIF(PAYROLL!O2:O107,"Mid") -> 15
AO45: Low | AP45: =COUNTIF(PAYROLL!O2:O107,"Low") -> 56
AO46: Review | AP46: =COUNTIF(PAYROLL!O2:O107,"Review") -> 0
AO48: Type | AP48: Count
AO49: Full-Time | AP49: =COUNTIF(Table1[Employment_Type],"Full-Time") -> 85
AO50: Contract | AP50: =COUNTIF(Table1[Employment_Type],"Contract") -> 16
AO51: Part-Time | AP51: =COUNTIF(Table1[Employment_Type],"Part-Time") -> 5

Sheet PAYSLIP
A2: Select Employee ID: | B2: EMP015
A4: GS ENTERPRISES
A5: New Delhi — 110008
A7: SALARY SLIP — JANUARY 2025
A9: Employee ID | C9: =B2 -> EMP015 | E9: Month | G9: 45658
A10: Employee Name | C10: =_xlfn.XLOOKUP(B2,Table1[Emp_ID],Table1[Full_Name ]) -> Dhruv | E10: Days Present | G10: =_xlfn.XLOOKUP(B2,Table2[Emp_ID],Table2[Total Present]) -> 23
A11: Department | C11: =_xlfn.XLOOKUP(B2,Table1[Emp_ID],Table1[Department]) -> Operations | E11: Days Absent | G11: =_xlfn.XLOOKUP(B2,Table2[Emp_ID],Table2[Total Absent]) -> 1
A12: Designation | C12: =_xlfn.XLOOKUP(B2,Table1[Emp_ID],Table1[Designation]) -> Executive | E12: Casual Leave | G12: =_xlfn.XLOOKUP(B2,Table2[Emp_ID],Table2[Casual Leave (CL)]) -> 0
A13: Date of Joining | C13: =_xlfn.XLOOKUP(B2,Table1[Emp_ID],Table1[Date_of_Joining]) -> 44997 | E13: Sick Leave | G13: =_xlfn.XLOOKUP(B2,Table2[Emp_ID],Table2[Sick Leave (SL)]) -> 2
A14: Employment Type | C14: =_xlfn.XLOOKUP(B2,Table1[Emp_ID],Table1[Employment_Type]) -> Full-Time | E14: Late Marks | G14: =_xlfn.XLOOKUP(B2,Table2[Emp_ID],Table2[Late Marks]) -> 0
A15: Bank Account | C15: =_xlfn.XLOOKUP(B2,Table1[Emp_ID],Table1[Bank_Account]) -> HDFC0006677 | E15: Attendance% | G15: =ROUND(_xlfn.XLOOKUP(B2,Table2[Emp_ID],Table2[Attendance %]),1)&"%" -> 96.2%
A17: EARNINGS | E17: DEDUCTIONS
A18: Basic Salary | D18: =_xlfn.XLOOKUP(B2,Table3[Emp_ID],Table3[Basic_Salary]) -> 24000 | E18: Provident Fund (12%) | H18: =IF(D18>15000,ROUND(D18*0.12,0),0) -> 2880
A19: HRA | D19: =_xlfn.XLOOKUP(B2,Table3[Emp_ID],Table3[HRA]) -> 7200 | E19: ESI (0.75%) | H19: =IF(D23<21000,ROUND(D23*0.0075,0),0) -> 0
A20: DA | D20: =_xlfn.XLOOKUP(B2,Table3[Emp_ID],Table3[DA]) -> 2400 | E20: Professional Tax | H20: =IF(D23<=10000,0,IF(D23<=15000,150,IF(D23<=25000,300,200))) -> 200
E21: LOP Deduction | H21: =ROUND((D18/26)*_xlfn.XLOOKUP(B2,Table2[Emp_ID],Table2[Total Absent]),0) -> 923
A23: Gross Salary | D23: =SUM(D18:D20) -> 33600 | E23: Total Deductions | H23: =SUM(H18:H21) -> 4003
A25: ="NET SALARY PAYABLE: ₹"&TEXT(D23-H23,"##,##,##0") -> NET SALARY PAYABLE: ₹29,597
